<?xml version="1.0" encoding="UTF-8"?>
<testng-results skipped="0" failed="2" ignored="0" total="2" passed="0">
  <reporter-output>
  </reporter-output>
  <suite name="Default suite" duration-ms="26683" started-at="2018-03-02T17:04:39Z" finished-at="2018-03-02T17:05:06Z">
    <groups>
    </groups>
    <test name="Default test" duration-ms="26683" started-at="2018-03-02T17:04:39Z" finished-at="2018-03-02T17:05:06Z">
      <class name="com.dac.testcases.LoginpageTests">
        <test-method status="PASS" signature="setup()[pri:0, instance:com.dac.testcases.LoginpageTests@146ba0ac]" name="setup" is-config="true" duration-ms="4034" started-at="2018-03-02T17:04:39Z" finished-at="2018-03-02T17:04:43Z">
          <reporter-output>
          </reporter-output>
        </test-method> <!-- setup -->
        <test-method status="FAIL" signature="invalid_login()[pri:1, instance:com.dac.testcases.LoginpageTests@146ba0ac]" name="invalid_login" duration-ms="14004" started-at="2018-03-02T17:04:43Z" finished-at="2018-03-02T17:04:57Z">
          <exception class="java.lang.AssertionError">
            <message>
              <![CDATA[expected [Invalid Password] but found [Invalid Password2]]]>
            </message>
            <full-stacktrace>
              <![CDATA[java.lang.AssertionError: expected [Invalid Password] but found [Invalid Password2]
at org.testng.Assert.fail(Assert.java:96)
at org.testng.Assert.failNotEquals(Assert.java:776)
at org.testng.Assert.assertEqualsImpl(Assert.java:137)
at org.testng.Assert.assertEquals(Assert.java:118)
at org.testng.Assert.assertEquals(Assert.java:453)
at org.testng.Assert.assertEquals(Assert.java:463)
at com.dac.testcases.LoginpageTests.invalid_login(LoginpageTests.java:44)
at sun.reflect.NativeMethodAccessorImpl.invoke0(Native Method)
at sun.reflect.NativeMethodAccessorImpl.invoke(Unknown Source)
at sun.reflect.DelegatingMethodAccessorImpl.invoke(Unknown Source)
at java.lang.reflect.Method.invoke(Unknown Source)
at org.testng.internal.MethodInvocationHelper.invokeMethod(MethodInvocationHelper.java:124)
at org.testng.internal.Invoker.invokeMethod(Invoker.java:580)
at org.testng.internal.Invoker.invokeTestMethod(Invoker.java:716)
at org.testng.internal.Invoker.invokeTestMethods(Invoker.java:988)
at org.testng.internal.TestMethodWorker.invokeTestMethods(TestMethodWorker.java:125)
at org.testng.internal.TestMethodWorker.run(TestMethodWorker.java:109)
at org.testng.TestRunner.privateRun(TestRunner.java:648)
at org.testng.TestRunner.run(TestRunner.java:505)
at org.testng.SuiteRunner.runTest(SuiteRunner.java:455)
at org.testng.SuiteRunner.runSequentially(SuiteRunner.java:450)
at org.testng.SuiteRunner.privateRun(SuiteRunner.java:415)
at org.testng.SuiteRunner.run(SuiteRunner.java:364)
at org.testng.SuiteRunnerWorker.runSuite(SuiteRunnerWorker.java:52)
at org.testng.SuiteRunnerWorker.run(SuiteRunnerWorker.java:84)
at org.testng.TestNG.runSuitesSequentially(TestNG.java:1208)
at org.testng.TestNG.runSuitesLocally(TestNG.java:1137)
at org.testng.TestNG.runSuites(TestNG.java:1049)
at org.testng.TestNG.run(TestNG.java:1017)
at org.testng.remote.AbstractRemoteTestNG.run(AbstractRemoteTestNG.java:114)
at org.testng.remote.RemoteTestNG.initAndRun(RemoteTestNG.java:251)
at org.testng.remote.RemoteTestNG.main(RemoteTestNG.java:77)
]]>
            </full-stacktrace>
          </exception> <!-- java.lang.AssertionError -->
          <reporter-output>
          </reporter-output>
        </test-method> <!-- invalid_login -->
        <test-method status="PASS" signature="TearDown_AM(org.testng.ITestResult)[pri:0, instance:com.dac.testcases.LoginpageTests@146ba0ac]" name="TearDown_AM" is-config="true" duration-ms="760" started-at="2018-03-02T17:04:57Z" finished-at="2018-03-02T17:04:58Z">
          <params>
            <param index="0">
              <value>
                <![CDATA[[TestResult name=invalid_login status=FAILURE method=LoginpageTests.invalid_login()[pri:1, instance:com.dac.testcases.LoginpageTests@146ba0ac] output={null}]]]>
              </value>
            </param>
          </params>
          <reporter-output>
          </reporter-output>
        </test-method> <!-- TearDown_AM -->
        <test-method status="FAIL" signature="valid_login()[pri:2, instance:com.dac.testcases.LoginpageTests@146ba0ac]" name="valid_login" duration-ms="7282" started-at="2018-03-02T17:04:58Z" finished-at="2018-03-02T17:05:05Z">
          <exception class="java.lang.AssertionError">
            <message>
              <![CDATA[expected [false] but found [true]]]>
            </message>
            <full-stacktrace>
              <![CDATA[java.lang.AssertionError: expected [false] but found [true]
at org.testng.Assert.fail(Assert.java:96)
at org.testng.Assert.failNotEquals(Assert.java:776)
at org.testng.Assert.assertFalse(Assert.java:65)
at org.testng.Assert.assertFalse(Assert.java:75)
at com.dac.testcases.LoginpageTests.valid_login(LoginpageTests.java:66)
at sun.reflect.NativeMethodAccessorImpl.invoke0(Native Method)
at sun.reflect.NativeMethodAccessorImpl.invoke(Unknown Source)
at sun.reflect.DelegatingMethodAccessorImpl.invoke(Unknown Source)
at java.lang.reflect.Method.invoke(Unknown Source)
at org.testng.internal.MethodInvocationHelper.invokeMethod(MethodInvocationHelper.java:124)
at org.testng.internal.Invoker.invokeMethod(Invoker.java:580)
at org.testng.internal.Invoker.invokeTestMethod(Invoker.java:716)
at org.testng.internal.Invoker.invokeTestMethods(Invoker.java:988)
at org.testng.internal.TestMethodWorker.invokeTestMethods(TestMethodWorker.java:125)
at org.testng.internal.TestMethodWorker.run(TestMethodWorker.java:109)
at org.testng.TestRunner.privateRun(TestRunner.java:648)
at org.testng.TestRunner.run(TestRunner.java:505)
at org.testng.SuiteRunner.runTest(SuiteRunner.java:455)
at org.testng.SuiteRunner.runSequentially(SuiteRunner.java:450)
at org.testng.SuiteRunner.privateRun(SuiteRunner.java:415)
at org.testng.SuiteRunner.run(SuiteRunner.java:364)
at org.testng.SuiteRunnerWorker.runSuite(SuiteRunnerWorker.java:52)
at org.testng.SuiteRunnerWorker.run(SuiteRunnerWorker.java:84)
at org.testng.TestNG.runSuitesSequentially(TestNG.java:1208)
at org.testng.TestNG.runSuitesLocally(TestNG.java:1137)
at org.testng.TestNG.runSuites(TestNG.java:1049)
at org.testng.TestNG.run(TestNG.java:1017)
at org.testng.remote.AbstractRemoteTestNG.run(AbstractRemoteTestNG.java:114)
at org.testng.remote.RemoteTestNG.initAndRun(RemoteTestNG.java:251)
at org.testng.remote.RemoteTestNG.main(RemoteTestNG.java:77)
]]>
            </full-stacktrace>
          </exception> <!-- java.lang.AssertionError -->
          <reporter-output>
          </reporter-output>
        </test-method> <!-- valid_login -->
        <test-method status="PASS" signature="TearDown_AM(org.testng.ITestResult)[pri:0, instance:com.dac.testcases.LoginpageTests@146ba0ac]" name="TearDown_AM" is-config="true" duration-ms="384" started-at="2018-03-02T17:05:05Z" finished-at="2018-03-02T17:05:06Z">
          <params>
            <param index="0">
              <value>
                <![CDATA[[TestResult name=valid_login status=FAILURE method=LoginpageTests.valid_login()[pri:2, instance:com.dac.testcases.LoginpageTests@146ba0ac] output={null}]]]>
              </value>
            </param>
          </params>
          <reporter-output>
          </reporter-output>
        </test-method> <!-- TearDown_AM -->
        <test-method status="PASS" signature="tearDownMethod()[pri:0, instance:com.dac.testcases.LoginpageTests@146ba0ac]" name="tearDownMethod" is-config="true" duration-ms="164" started-at="2018-03-02T17:05:06Z" finished-at="2018-03-02T17:05:06Z">
          <reporter-output>
          </reporter-output>
        </test-method> <!-- tearDownMethod -->
      </class> <!-- com.dac.testcases.LoginpageTests -->
    </test> <!-- Default test -->
  </suite> <!-- Default suite -->
</testng-results>
